<?xml version="1.0"?>

<robot name="panda" xmlns:xacro="http://www.ros.org/wiki/xacro">

    <!-- Add argument for FT sensor -->
    <xacro:arg name="use_ft_sensor" default="false"/>

    <!-- panda Links -->
    <link name="panda_link0">
        <inertial>
            <origin rpy="0 0 0" xyz="-0.041018 -0.00014 0.049974" />
            <mass value="0.629769" />
            <inertia ixx="0.00315" ixy="8.2904E-07" ixz="0.00015" iyy="0.00388" iyz="8.2299E-06"
                izz="0.004285" />
        </inertial>
        <visual>
            <geometry>
                <mesh filename="package://virtual_tactile_pad/urdf/meshes/link0.stl" />
            </geometry>
            <material name="panda_gray" />
        </visual>
        <collision>
            <geometry>
                <mesh filename="package://virtual_tactile_pad/urdf/meshes/link0.stl" />
            </geometry>
        </collision>
    </link>
    <link name="panda_link1">
        <inertial>
            <origin rpy="0 0 0" xyz="3.875e-03 2.081e-03 -0.1750" />
            <mass value="4.970684" />
            <inertia ixx="7.0337e-01" ixy="-1.3900e-04" ixz="6.7720e-03" iyy="7.0661e-01"
                iyz="1.9169e-02" izz="9.1170e-03" />
        </inertial>
        <visual>
            <geometry>
                <mesh filename="package://virtual_tactile_pad/urdf/meshes/link1.stl" />
            </geometry>
            <material name="panda_white" />
        </visual>
        <collision>
            <geometry>
                <mesh filename="package://virtual_tactile_pad/urdf/meshes/link1.stl" />
            </geometry>
        </collision>
    </link>
    <joint name="panda_joint1" type="revolute">
        <safety_controller k_position="100.0" k_velocity="40.0" soft_lower_limit="-2.8973"
            soft_upper_limit="2.8973" />
        <origin rpy="0 0 0" xyz="0 0 0.333" />
        <parent link="panda_link0" />
        <child link="panda_link1" />
        <axis xyz="0 0 1" />
        <limit effort="87" lower="-2.8973" upper="2.8973" velocity="2.1750" />
        <dynamics damping="10.0" friction="5.0" />
    </joint>
    <link name="panda_link2">
        <inertial>
            <origin rpy="0 0 0" xyz="-3.141e-03 -2.872e-02 3.495e-03" />
            <mass value="0.646926" />
            <inertia ixx="7.9620e-03" ixy="-3.9250e-03" ixz="1.0254e-02" iyy="2.8110e-02"
                iyz="7.0400e-04" izz="2.5995e-02" />
        </inertial>
        <visual>
            <geometry>
                <mesh filename="package://virtual_tactile_pad/urdf/meshes/link2.stl" />
            </geometry>
            <material name="panda_white" />
        </visual>
        <collision>
            <geometry>
                <mesh filename="package://virtual_tactile_pad/urdf/meshes/link2.stl" />
            </geometry>
        </collision>
    </link>
    <joint name="panda_joint2" type="revolute">
        <safety_controller k_position="100.0" k_velocity="40.0" soft_lower_limit="-1.7628"
            soft_upper_limit="1.7628" />
        <origin rpy="-1.57079632679 0 0" xyz="0 0 0" />
        <parent link="panda_link1" />
        <child link="panda_link2" />
        <axis xyz="0 0 1" />
        <limit effort="87" lower="-1.7628" upper="1.7628" velocity="2.1750" />
        <dynamics damping="5.0" friction="2.0" />
    </joint>
    <link name="panda_link3">
        <inertial>
            <origin rpy="0 0 0" xyz="2.7518e-02 3.9252e-02 -6.6502e-02" />
            <mass value="3.228604" />
            <inertia ixx="3.7242e-02" ixy="-4.7610e-03" ixz="-1.1396e-02" iyy="3.6155e-02"
                iyz="-1.2805e-02" izz="1.0830e-02" />
        </inertial>
        <visual>
            <geometry>
                <mesh filename="package://virtual_tactile_pad/urdf/meshes/link3.stl" />
            </geometry>
            <material name="panda_white" />
        </visual>
        <collision>
            <geometry>
                <mesh filename="package://virtual_tactile_pad/urdf/meshes/link3.stl" />
            </geometry>
        </collision>
    </link>
    <joint name="panda_joint3" type="revolute">
        <safety_controller k_position="100.0" k_velocity="40.0" soft_lower_limit="-2.8973"
            soft_upper_limit="2.8973" />
        <origin rpy="1.57079632679 0 0" xyz="0 -0.316 0" />
        <parent link="panda_link2" />
        <child link="panda_link3" />
        <axis xyz="0 0 1" />
        <limit effort="87" lower="-2.8973" upper="2.8973" velocity="2.1750" />
        <dynamics damping="5.0" friction="2.0" />
    </joint>
    <link name="panda_link4">
        <inertial>
            <origin rpy="0 0 0" xyz="-5.317e-02 1.04419e-01 2.7454e-02" />
            <mass value="3.587895" />
            <inertia ixx="2.5853e-02" ixy="7.7960e-03" ixz="-1.3320e-03" iyy="1.9552e-02"
                iyz="8.6410e-03" izz="2.8323e-02" />
        </inertial>
        <visual>
            <geometry>
                <mesh filename="package://virtual_tactile_pad/urdf/meshes/link4.stl" />
            </geometry>
            <material name="panda_white" />
        </visual>
        <collision>
            <geometry>
                <mesh filename="package://virtual_tactile_pad/urdf/meshes/link4.stl" />
            </geometry>
        </collision>
    </link>
    <joint name="panda_joint4" type="revolute">
        <safety_controller k_position="100.0" k_velocity="40.0" soft_lower_limit="-3.0718"
            soft_upper_limit="0.0175" />
        <origin rpy="1.57079632679 0 0" xyz="0.0825 0 0" />
        <parent link="panda_link3" />
        <child link="panda_link4" />
        <axis xyz="0 0 1" />
        <limit effort="87" lower="-3.0718" upper="-0.0698" velocity="2.1750" />
        <dynamics damping="1.0" friction="0.5" />
    </joint>
    <link name="panda_link5">
        <inertial>
            <origin rpy="0 0 0" xyz="-1.1953e-02 4.1065e-02 -3.8437e-02" />
            <mass value="1.225946" />
            <inertia ixx="3.5549e-02" ixy="-2.1170e-03" ixz="-4.0370e-03" iyy="2.9474e-02"
                iyz="2.2900e-04" izz="8.6270e-03" />
        </inertial>
        <visual>
            <geometry>
                <mesh filename="package://virtual_tactile_pad/urdf/meshes/link5.stl" />
            </geometry>
            <material name="panda_white" />
        </visual>
        <collision>
            <geometry>
                <mesh filename="package://virtual_tactile_pad/urdf/meshes/link5.stl" />
            </geometry>
        </collision>
    </link>
    <joint name="panda_joint5" type="revolute">
        <safety_controller k_position="100.0" k_velocity="40.0" soft_lower_limit="-2.8973"
            soft_upper_limit="2.8973" />
        <origin rpy="-1.57079632679 0 0" xyz="-0.0825 0.384 0" />
        <parent link="panda_link4" />
        <child link="panda_link5" />
        <axis xyz="0 0 1" />
        <limit effort="12" lower="-2.8973" upper="2.8973" velocity="2.6100" />
        <dynamics damping="2.0" friction="1.0" />
    </joint>
    <link name="panda_link6">
        <inertial>
            <origin rpy="0 0 0" xyz="6.0149e-02 -1.4117e-02 -1.0517e-02" />
            <mass value="1.666555" />
            <inertia ixx="1.9640e-03" ixy="1.0900e-04" ixz="-1.1580e-03" iyy="4.3540e-03"
                iyz="3.4100e-04" izz="5.4330e-03" />
        </inertial>
        <visual>
            <geometry>
                <mesh filename="package://virtual_tactile_pad/urdf/meshes/link6.stl" />
            </geometry>
            <material name="panda_white" />
        </visual>
        <collision>
            <geometry>
                <mesh filename="package://virtual_tactile_pad/urdf/meshes/link6.stl" />
            </geometry>
        </collision>
    </link>
    <joint name="panda_joint6" type="revolute">
        <safety_controller k_position="100.0" k_velocity="40.0" soft_lower_limit="-0.0175"
            soft_upper_limit="3.7525" />
        <origin rpy="1.57079632679 3.141592654 0" xyz="0 0 0" />
        <parent link="panda_link5" />
        <child link="panda_link6" />
        <axis xyz="0 0 1" />
        <limit effort="12" lower="-0.0175" upper="3.7525" velocity="2.6100" />
        <dynamics damping="1.0" friction="0.5" />
    </joint>
    <link name="panda_link7">
        <inertial>
            <origin rpy="0 0 0" xyz="1.0517e-02 -4.252e-03 6.1597e-02" />
            <mass value="7.35522e-01" />
            <inertia ixx="1.2516e-02" ixy="-4.2800e-04" ixz="-1.1960e-03" iyy="1.0027e-02"
                iyz="-7.4100e-04" izz="4.8150e-03" />
        </inertial>
        <visual>
            <geometry>
                <mesh filename="package://virtual_tactile_pad/urdf/meshes/link7.stl" />
            </geometry>
            <material name="panda_white" />
        </visual>
        <collision>
            <geometry>
                <mesh filename="package://virtual_tactile_pad/urdf/meshes/link7.stl" />
            </geometry>
        </collision>
    </link>
    <joint name="panda_joint7" type="revolute">
        <safety_controller k_position="100.0" k_velocity="40.0" soft_lower_limit="-2.8973"
            soft_upper_limit="2.8973" />
        <origin rpy="1.57079632679 0 0" xyz="0.088 0 0" />
        <parent link="panda_link6" />
        <child link="panda_link7" />
        <axis xyz="0 0 1" />
        <limit effort="12" lower="-2.8973" upper="2.8973" velocity="2.6100" />
        <dynamics damping="1.0" friction="0.5" />
    </joint>
    <link name="panda_link8">
        <inertial>
            <origin rpy="0 0 0" xyz="0 0 0" />
            <mass value="0.0" />
            <inertia ixx="0.001" ixy="0.0" ixz="0.0" iyy="0.001" iyz="0.0" izz="0.001" />
        </inertial>
    </link>
    <joint name="panda_joint8" type="fixed">
        <origin rpy="0 0 -1.57079632679" xyz="0 0 0.107" />
        <parent link="panda_link7" />
        <child link="panda_link8" />
        <axis xyz="0 0 0" />
    </joint>

    <!-- Conditionally include FT sensor or direct mounting -->
    <xacro:if value="$(arg use_ft_sensor)">
        <!-- ati-net-gamma Link -->
        <link name="ati_net_gamma">
            <visual>
                <origin xyz="0 0 0" rpy="0 0 0.5" />
                <geometry>
                    <mesh filename="package://virtual_tactile_pad/urdf/meshes/ati_net_gamma.stl" />
                </geometry>
                <material name="ati_net_gamma_gray" />
            </visual>
            <collision>
                <origin xyz="0 0 0" rpy="0 0 0.5" />
                <geometry>
                    <mesh filename="package://virtual_tactile_pad/urdf/meshes/ati_net_gamma.stl" />
                </geometry>
            </collision>
            <inertial>
                <mass value="1.145" />
                <origin xyz="0 0 0" rpy="0 0 0.5" />
                <inertia ixx="0.4644" ixy="0.035" ixz="0.00153" iyy="0.6389" iyz="0.00056" izz="0.9040" />
            </inertial>
        </link>

        <joint name="panda_joint_to_ati_gamma" type="fixed">
            <parent link="panda_link8" />
            <child link="ati_net_gamma" />
            <origin xyz="0 0 0.0187" rpy="0 3.141592654 0.0" />
        </joint>

        <!-- Mounting Pad Link -->
        <link name="mounting_pad">
            <visual>
                <geometry>
                    <mesh filename="package://virtual_tactile_pad/urdf/meshes/mounting_pad.stl" />
                </geometry>
                <material name="mounting_pad_gray" />
            </visual>
            <collision>
                <geometry>
                    <mesh filename="package://virtual_tactile_pad/urdf/meshes/mounting_pad.stl" />
                </geometry>
            </collision>
            <inertial>
                <mass value="0.184292" />
                <inertia ixx="0.0000361368" ixy="0.0" ixz="0.0" iyy="0.000046691" iyz="0.0"
                    izz="0.00007688" />
            </inertial>
        </link>
        <joint name="ati_net_gamma_to_mounting_pad" type="fixed">
            <parent link="ati_net_gamma" />
            <child link="mounting_pad" />
            <origin xyz="0 0 -0.0146" rpy="0 3.141592654 -0.023796327" />
        </joint>
    </xacro:if>

    <xacro:unless value="$(arg use_ft_sensor)">
        <!-- Mounting Pad Link -->
        <link name="mounting_pad">
            <visual>
                <geometry>
                    <mesh filename="package://virtual_tactile_pad/urdf/meshes/mounting_pad.stl" />
                </geometry>
                <material name="mounting_pad_gray" />
            </visual>
            <collision>
                <geometry>
                    <mesh filename="package://virtual_tactile_pad/urdf/meshes/mounting_pad.stl" />
                </geometry>
            </collision>
            <inertial>
                <mass value="0.184292" />
                <inertia ixx="0.0000361368" ixy="0.0" ixz="0.0" iyy="0.000046691" iyz="0.0"
                    izz="0.00007688" />
            </inertial>
        </link>
        <!-- Direct joint from panda_link8 to mounting_pad -->
        <joint name="panda_link8_to_mounting_pad" type="fixed">
            <parent link="panda_link8" />
            <child link="mounting_pad" />
            <origin xyz="0 0 0" rpy="0 0 0" />  
        </joint>
    </xacro:unless>
    
    <!-- Pad Link -->
    <link name="pad">
        <visual>
            <geometry>
                <mesh filename="package://virtual_tactile_pad/urdf/meshes/pad.stl" />
            </geometry>
            <material name="pad_blue" />
        </visual>
        <collision>
            <geometry>
                <mesh filename="package://virtual_tactile_pad/urdf/meshes/pad.stl" />
            </geometry>
        </collision>
        <inertial>
            <mass value="0.145376" />
            <inertia ixx="0.0002345" ixy="0.0" ixz="0.0" iyy="0.0004074" iyz="0.0" izz="0.0001733" />
        </inertial>
    </link>
    <joint name="mounting_pad_to_pad" type="fixed">
        <parent link="mounting_pad" />
        <child link="pad" />
        <origin xyz="0 0 0" rpy="0 0 0." />
    </joint>
    <!-- material definitions -->
    <material name="panda_white">
        <color rgba="1. 1. 1. 1." />
    </material>
    <material name="panda_gray">
        <color rgba="0.8 0.8 0.8 1." />
    </material>
    <material name="pad_blue">
        <color rgba="0.68 0.85 0.9 0.7" />
    </material>
    <material name="mounting_pad_gray">
        <color rgba="0.6 0.6 0.6 1." />
    </material>
    <material name="ati_net_gamma_gray">
        <color rgba="0.4 0.4 0.4 1." />
    </material>
</robot>